<?xml version="1.0"?>
<robot name="baocao_robot">
  <!-- Dummy link làm root link -->
  <link name="dummy_link"/>

  <!-- Joint nối dummy_link với base_link -->
  <joint name="dummy_to_base" type="fixed">
    <parent link="dummy_link"/>
    <child link="base_link"/>
    <origin xyz="0 0 0" rpy="0 0 0"/>
  </joint>

  <link name="base_link">
    <visual>
      <geometry>
        <box size="0.4 0.4 0.1"/>
      </geometry>
      <material name="blue">
        <color rgba="0 0 1 1"/>
      </material>
    </visual>
    <collision>
      <geometry>
        <box size="0.4 0.4 0.1"/>
      </geometry>
    </collision>
    <inertial>
      <mass value="5"/>
      <origin xyz="0 0 0" rpy="0 0 0"/>
      <inertia ixx="0.07083" ixy="0.0" ixz="0.0" iyy="0.07083" iyz="0.0" izz="0.666"/>
    </inertial>
  </link>

  <link name="before_left_wheel">
    <visual>
      <geometry>
        <cylinder length="0.05" radius="0.05"/>
      </geometry>
      <material name="red_material">
        <color rgba="1 1 0 1"/>
      </material>
    </visual>
    <collision>
      <geometry>
        <cylinder length="0.05" radius="0.05"/>
      </geometry>
      <surface>
        <friction>
          <ode>
            <mu>0.1</mu>
            <mu2>0.1</mu2>
          </ode>
        </friction>
      </surface>
    </collision>
    <inertial>
      <mass value="0.1"/>
      <origin xyz="0 0 0" rpy="0 0 0"/>
      <inertia ixx="0.0083" ixy="0.0" ixz="0.0" iyy="0.0083" iyz="0.0" izz="0.000125"/>
    </inertial>
  </link>

  <joint name="joint_before_left" type="continuous">
    <parent link="base_link"/>
    <child link="before_left_wheel"/>
    <origin xyz="0.14 0.125 -0.05" rpy="0 1.570796 1.570796"/>
    <axis xyz="0 0 1"/>
    <limit effort="100.0" velocity="10.0"/>
  </joint>

  <link name="before_right_wheel">
    <visual>
      <geometry>
        <cylinder length="0.05" radius="0.05"/>
      </geometry>
      <material name="green_material">
        <color rgba="1 1 0 1"/>
      </material>
    </visual>
    <collision>
      <geometry>
        <cylinder length="0.05" radius="0.05"/>
      </geometry>
      <surface>
        <friction>
          <ode>
            <mu>0.1</mu>
            <mu2>0.1</mu2>
          </ode>
        </friction>
      </surface>
    </collision>
    <inertial>
      <mass value="0.1"/>
      <origin xyz="0 0 0" rpy="0 0 0"/>
      <inertia ixx="0.0083" ixy="0.0" ixz="0.0" iyy="0.0083" iyz="0.0" izz="0.000125"/>
    </inertial>
  </link>

  <joint name="joint_before_right" type="continuous">
    <parent link="base_link"/>
    <child link="before_right_wheel"/>
    <origin xyz="0.14 -0.125 -0.05" rpy="0 1.570796 1.570796"/>
    <axis xyz="0 0 1"/>
    <limit effort="100.0" velocity="10.0"/>
  </joint>

  <link name="after_left_wheel">
    <visual>
      <geometry>
        <cylinder length="0.05" radius="0.05"/>
      </geometry>
      <material name="yellow_material">
        <color rgba="1 1 0 1"/>
      </material>
    </visual>
    <collision>
      <geometry>
        <cylinder length="0.05" radius="0.05"/>
      </geometry>
      <surface>
        <friction>
          <ode>
            <mu>0.1</mu>
            <mu2>0.1</mu2>
          </ode>
        </friction>
      </surface>
    </collision>
    <inertial>
      <mass value="0.1"/>
      <origin xyz="0 0 0" rpy="0 0 0"/>
      <inertia ixx="0.0083" ixy="0.0" ixz="0.0" iyy="0.0083" iyz="0.0" izz="0.000125"/>
    </inertial>
  </link>

  <joint name="joint_after_left" type="continuous">
    <parent link="base_link"/>
    <child link="after_left_wheel"/>
    <origin xyz="-0.14 0.125 -0.05" rpy="0 1.570796 1.570796"/>
    <axis xyz="0 0 1"/>
    <limit effort="100.0" velocity="10.0"/>
  </joint>

  <link name="after_right_wheel">
    <visual>
      <geometry>
        <cylinder length="0.05" radius="0.05"/>
      </geometry>
      <material name="grey_material">
        <color rgba="0.5 0.5 0.5 1"/>
      </material>
    </visual>
    <collision>
      <geometry>
        <cylinder length="0.05" radius="0.05"/>
      </geometry>
      <surface>
        <friction>
          <ode>
            <mu>0.1</mu>
            <mu2>0.1</mu2>
          </ode>
        </friction>
      </surface>
    </collision>
    <inertial>
      <mass value="0.1"/>
      <origin xyz="0 0 0" rpy="0 0 0"/>
      <inertia ixx="0.0083" ixy="0.0" ixz="0.0" iyy="0.0083" iyz="0.0" izz="0.000125"/>
    </inertial>
  </link>

  <joint name="joint_after_right" type="continuous">
    <parent link="base_link"/>
    <child link="after_right_wheel"/>
    <origin xyz="-0.14 -0.125 -0.05" rpy="0 1.570796 1.570796"/>
    <axis xyz="0 0 1"/>
    <limit effort="100.0" velocity="10.0"/>
  </joint>

  <link name="lidar_link">
    <visual>
      <geometry>
        <box size="0.1 0.1 0.05"/>
      </geometry>
      <material name="lidar">
        <color rgba="0.0 1.0 0.0 1.0"/>
      </material>
    </visual>
    <collision>
      <geometry>
        <box size="0.1 0.1 0.05"/>
      </geometry>
    </collision>
    <inertial>
      <mass value="0.1"/>
      <inertia ixx="0.0001042" iyy="0.0001042" izz="0.0001667" ixy="0.0" ixz="0.0" iyz="0.0"/>
    </inertial>
  </link>

  <joint name="lidar_joint" type="fixed">
    <parent link="base_link"/>
    <child link="lidar_link"/>
    <origin xyz="0 0 0.05"/>
  </joint>

  <gazebo reference="lidar_link">
    <sensor type="ray" name="lidar_sensor">
      <update_rate>40</update_rate>
      <ray>
        <scan>
          <horizontal>
            <samples>360</samples>
            <resolution>1.0</resolution>
            <min_angle>-1.57</min_angle>
            <max_angle>1.57</max_angle>
          </horizontal>
        </scan>
        <range>
          <min>0.1</min>
          <max>10.0</max>
          <resolution>0.01</resolution>
        </range>
      </ray>
      <plugin name="gazebo_ros_laser" filename="libgazebo_ros_laser.so">
        <topicName>/scan</topicName>
        <frameName>lidar_link</frameName>
      </plugin>
    </sensor>
  </gazebo>

  <link name="camera_link">
    <visual>
      <geometry>
        <box size="0.1 0.1 0.05"/>
      </geometry>
      <material name="camera">
        <color rgba="0.0 1.0 0.0 1.0"/>
      </material>
    </visual>
    <collision>
      <geometry>
        <box size="0.1 0.1 0.05"/>
      </geometry>
    </collision>
    <inertial>
      <mass value="0.1"/>
      <inertia ixx="0.0001042" iyy="0.0001042" izz="0.0001667" ixy="0.0" ixz="0.0" iyz="0.0"/>
    </inertial>
  </link>

  <joint name="camera_joint" type="fixed">
    <parent link="lidar_link"/>
    <child link="camera_link"/>
    <origin xyz="0 0 0.2"/>
  </joint>

  <gazebo reference="camera_link">
    <sensor type="camera" name="camera_sensor">
      <update_rate>30</update_rate>
      <camera>
        <horizontal_fov>1.3962634</horizontal_fov>
        <image>
          <width>640</width>
          <height>480</height>
          <format>R8G8B8</format>
        </image>
        <clip>
          <near>0.1</near>
          <far>100</far>
        </clip>
      </camera>
      <plugin name="gazebo_ros_camera" filename="libgazebo_ros_camera.so">
        <alwaysOn>true</alwaysOn>
        <updateRate>30</updateRate>
        <cameraName>camera</cameraName>
        <imageTopicName>image_raw</imageTopicName>
        <cameraInfoTopicName>camera_info</cameraInfoTopicName>
        <frameName>camera_link</frameName>
      </plugin>
    </sensor>
  </gazebo>

<gazebo>
    <plugin name="gazebo_ros_control" filename="libgazebo_ros_control.so">
        <robotNamespace>/</robotNamespace>
        <robotSimType>gazebo_ros_control/DefaultRobotHWSim</robotSimType>
        <legacyModeNS>true</legacyModeNS>
    </plugin>
</gazebo>

<transmission name="tran_before_left">
  <type>transmission_interface/SimpleTransmission</type>
  <joint name="joint_before_left">
    <hardwareInterface>hardware_interface/VelocityJointInterface</hardwareInterface>
  </joint>
  <actuator name="motor_before_left">
    <hardwareInterface>hardware_interface/VelocityJointInterface</hardwareInterface>
    <mechanicalReduction>1</mechanicalReduction>
  </actuator>
</transmission>

<transmission name="tran_before_right">
  <type>transmission_interface/SimpleTransmission</type>
  <joint name="joint_before_right">
    <hardwareInterface>hardware_interface/VelocityJointInterface</hardwareInterface>
  </joint>
  <actuator name="motor_before_right">
    <hardwareInterface>hardware_interface/VelocityJointInterface</hardwareInterface>
    <mechanicalReduction>1</mechanicalReduction>
  </actuator>
</transmission>

<transmission name="tran_after_left">
  <type>transmission_interface/SimpleTransmission</type>
  <joint name="joint_after_left">
    <hardwareInterface>hardware_interface/VelocityJointInterface</hardwareInterface>
  </joint>
  <actuator name="motor_after_left">
    <hardwareInterface>hardware_interface/VelocityJointInterface</hardwareInterface>
    <mechanicalReduction>1</mechanicalReduction>
  </actuator>
</transmission>

<transmission name="tran_after_right">
  <type>transmission_interface/SimpleTransmission</type>
  <joint name="joint_after_right">
    <hardwareInterface>hardware_interface/VelocityJointInterface</hardwareInterface>
  </joint>
  <actuator name="motor_after_right">
    <hardwareInterface>hardware_interface/VelocityJointInterface</hardwareInterface>
    <mechanicalReduction>1</mechanicalReduction>
  </actuator>
</transmission>

</robot>


